Workbook

Sheet DANH SACH
A1: =SUBTOTAL(3,A3:A2991) -> 1387 | B1: Đơn vị | C1: Tên đơn vị | D1: Loại KHách hàng | E1: Thông tin đơn hàng | U1: Đặc điểm đơn hàng | AJ1: Công nợ | AM1: Yêu cầu thu gom | AS1: Lịch sử chăm sóc KHách hàng | AW1: KPI & mục tiêu Đã cam kết | AY1: Nhóm KHách hàng | BD1: Doanh thu tháng 12/2025 | BE1: Doanh thu tháng 01/2026 | BF1: Doanh thu tháng 02/2026 (01/02-22/02) | BG1: Doanh thu 3 tháng | BH1: THÔNG TIN CHI TIẾT | BI1: GHI CHÚ | BJ1: Mã BC | BK1: Tên BC/VHX | BL1: BĐP/X | BM1: Cước đặc thù | BN1: Người rà soát bàn giao TTKD | BO1: Người rà soát bàn giao TTVH | BP1: Đơn vị đã gắn HĐ trên CMS | BQ1: Đã gửi HĐ vật lý lên TTKD | BR1: Tên đơn vị
A2: TT | E2: Mã CRM/CMS | F2: Tên KHách hàng | G2: Địa chỉ | H2: Điện thoại | I2: Người liên hệ | J2: Mã CRM/CMS | K2: Mã số thuế | L2: Số hợp đồng | M2: Thời hạn hợp đồng | N2: Thời hạn kết thúc | O2: Phụ lục, thoả thuận bổ sung Hợp đồng | P2: Thời gian, quy định việc thanh toán cước BCCP ghi nợ | Q2: Hình thức, thời gian thanh toán tiền thu hộ COD | R2: Số tài KHoản nhận tiền thu hộ COD, phí ship | S2: Trạng thái hoạt động | T2: Người quản lý KHách hàng (Họ tên, số điện thoại, email) | U2: Dịch vụ sử dụng | V2: Dịch vụ GTGT KHác | W2: Nội dung hàng hóa gửi | X2: KHối lượng dự kiến/bưu gửi | Y2: Sản lượng bình quân/ngày | Z2: Doanh thu bình quân/ngày | AA2: Hình thức phát hành: KH dùng My VNP/exel/thủ công…. | AB2: Bưu cục ghi nhận doanh thu (số hiệu bưu cục, tên bưu cục) | AC2: Tài KHoản trên Portal KHL ghi nhận doanh thu | AD2: Chú dẫn yêu cầu chuyển phát | AE2: Chỉ tiêu thời gian toàn trình dịch vụ | AF2: Yêu cầu KHác: - Gia công, đóng gói - Thuê KHo,... (nếu có) - KHác biệt về thời gian cutoff (nếu có) - ......(nếu có) | AG2: KHiếu nại, chốt phạt bồi thường (KHác biệt nếu có) | AH2: [ ] KHách hàng có cấu hình hệ thống đặc biệt cần duy trì? | AI2: [ ] Có dịch vụ tuỳ chỉnh hay tích hợp đặc thù? | AJ2: [ ] KHách hàng còn công nợ chưa thanh toán? | AK2: [ ] Có lịch trình thu hồi hoặc xử lý công nợ? | AL2: Hình thức phạt đối với chậm trả nợ | AM2: Địa chỉ thu gom (chi tiết đến phường/xã, quận/huyện,..) | AN2: Thời gian thu gom | AO2: Tần suất thu gom | AP2: Sản lượng thu gom | AQ2: Phương tiện thu gom | AR2: KHác biệt thu gom (nếu có) | AS2: [ ] Tương tác gần nhất với KHách hàng | AT2: [ ] Ghi chú yêu cầu đặc biệt hoặc sự cố đang xử lý | AU2: [ ] Cam kết dịch vụ Đã thực hiện | AV2: [ ] Kế hoạch chăm sóc định kỳ | AW2: [ ] Cam kết chất lượng hoặc KPI giữa KHách hàng và Trung tâm Kinh doanh | AX2: [ ] Theo dõi mức độ hoàn thành và kế hoạch tiếp tục | AY2: KHách hàng sàn TMĐT | AZ2: KH tạo đơn bằng phần mềm bán hàng | BA2: KH tạo đơn và gửi thông tin qua API cho BĐVN | BB2: Tạo đơn trên PM MyVNP | BC2: Tạo đơn trên phần mềm Portal KHL | BH2: THÔNG TIN CHI TIẾT
A3: 1 | B3: 5310 | C3: Bưu điện TT Thuận Hóa - Phú Xuân | D3: SME | E3: T004890545 | F3: Công Ty Cổ Phần Toyota Huế | G3: Lô C, KĐT Phú Mỹ An, Đường Tố Hữu, An Đông, TP Huế | H3: 02436299696 | I3: Lê Thế Vỹ | J3: T004890545 | K3: 3301635376 | L3: HĐ54-2022_HĐBC_BĐTPH-MTL | M3: 01/5/2022 | N3: Không xác định | P3: 1-2 lần/tháng | S3: Đang hoạt động | T3: HỒ VĂN KỲ | U3: ETN001 | W3: Thư | X3: 17.14 | Y3: 2 | Z3: 51292 | AB3: 533810 | AC3: 533810_dungntt | AE3: Thực hiện theo quy định của TCT | AJ3: 3181837 | AK3: Đang liên hệ thanh toán | AM3: Lô C, KĐT Phú Mỹ An, Đường Tố Hữu, An Đông, TP Huế | AN3: 14h00-17h00 | AO3: 1 lần/ngày | AP3: 66 | AQ3: xe máy | AS3: 45855 | BB3: X | BD3: 1862866 | BE3: 2425140 | BF3: 813058 | BG3: =SUM(BD3:BF3) -> 5101064 | BH3: Hồ sơ vật lý và hồ sơ điện tử | BI3: Phát - Long | BJ3: 533810 | BK3: Thuỷ An | BL3: Phường An Cựu | BP3: X | BQ3: X | BR3: Bưu điện TT Thuận Hóa - Phú Xuân
A4: 2 | B4: 5310 | C4: Bưu điện TT Thuận Hóa - Phú Xuân | D4: Shop | E4: C001395675 | F4: VÕ HOÀNG MINH | G4: Đường số 7, An Cựu City, P An Đông, TP Huế | H4: 0932436536 | I4: VÕ HOÀNG MINH | J4: C001395675 | L4: 151/HĐBC-BĐTP/VHM | M4: 43685 | N4: Không xác định | P4: Thanh toán ngay khi gửi | S4: Đang hoạt động | T4: PHẠM THỊ THANH UYÊN | U4: ETN011 | W4: TRANH VE | X4: 3.5743333 | Y4: 0.1 | Z4: 6994.4 | AB4: 533810 | AC4: 533810_dungntt | AE4: Theo quy định TCT | AF4: Không có yêu cầu khác. | AJ4: đã thanh toán | AM4: Đường số 7, An Cựu City, P An Đông, TP Huế | AN4: 09h00-11h00; 15h00-17h00 | AO4: 1-2 lần/tuần | AP4: 3 | AQ4: Xe máy | AS4: 45782 | BB4: X | BD4: 232290 | BE4: 175356 | BF4: 0 | BG4: =SUM(BD4:BF4) -> 407646 | BH4: Hồ sơ vật lý và hồ sơ điện tử | BI4: Phát - Long | BJ4: 533810 | BK4: Thuỷ An | BL4: Phường An Cựu | BP4: X | BQ4: X | BR4: Bưu điện TT Thuận Hóa - Phú Xuân
A5: 3 | B5: 5310 | C5: Bưu điện TT Thuận Hóa - Phú Xuân | D5: SME | E5: T001799661 | F5: CÔNG TY TNHH TM QUỐC HÙNG | G5: 86 HÙNG VƯƠNG, TP HUẾ | H5: 0989020237 | I5: Nguyễn Trần Như Ý | J5: T001799661 | K5: 3300338476 | L5: 384/HĐBC/BĐTPH-CTQUOCHUNG | M5: 44169 | N5: Không xác định | O5: Không có | P5: 01 tháng/lần Thanh toán tại địa chỉ bên A | S5: Đang hoạt động | T5: HỒ VĂN KỲ | U5: ETN011, ETN011 | W5: Phụ tùng xe máy | X5: 0.41 | Y5: 0.33 | Z5: 13125.6 | AB5: 533810 | AD5: SỐ ĐT NTO GHI TRÊN ĐƠN HÀNG.TSK | AE5: Theo quy định TCT | AF5: Không có yêu cầu khác. | AJ5: 759.888 | AK5: đang thanh toán | AM5: 86 HÙNG VƯƠNG, TP HUẾ | AN5: 09h00-11h00; 15h00-17h00 | AO5: 1-2 lần/tuần | AP5: 10 | AQ5: Xe máy | AS5: 45869 | BC5: X | BD5: 0 | BE5: 0 | BF5: 18000 | BG5: =SUM(BD5:BF5) -> 18000 | BH5: Hồ sơ vật lý và hồ sơ điện tử | BI5: Phát - Long | BJ5: 533810 | BK5: Thuỷ An | BL5: Phường An Cựu | BP5: X | BQ5: X | BR5: Bưu điện TT Thuận Hóa - Phú Xuân
A6: 4 | B6: 5310 | C6: Bưu điện TT Thuận Hóa - Phú Xuân | D6: SME | E6: T001456556 | F6: Công ty luật TNHH Nhật Nam và cộng sự | G6: 52 Hoàng Văn Thụ, P An Đông, TP Huế | H6: 0234.3936155 | I6: Trần Nhật Nam | J6: T001456556 | K6: 3301516202 | L6: 149/HĐBC-BĐTP/TNN | M6: 43685 | N6: Không xác định | O6: Không có | P6: Thanh toán vào tháng sau | S6: Đang hoạt động | T6: PHẠM THỊ THANH UYÊN | U6: ETN001 | X6: 0.07 | Y6: 0.87 | Z6: 12283.2 | AB6: 533810 | AC6: 533810_dungntt | AD6: SỐ ĐT NTO GHI TRÊN ĐƠN HÀNG.TKS | AE6: Theo quy định TCT | AF6: Không có yêu cầu khác. | AJ6: 2,605,824 | AK6: khách hàng chậm trả | AM6: 52 Hoàng Văn Thụ, P An Đông, TP Huế | AN6: 09h00-11h00; 15h00-17h00 | AO6: 1-2 lần/tuần | AP6: 26 | AQ6: Xe máy | AS6: 45869 | BC6: X | BD6: 459600 | BE6: 223200 | BF6: 138400 | BG6: =SUM(BD6:BF6) -> 821200 | BH6: Hồ sơ vật lý và hồ sơ điện tử | BI6: Phát - Long | BJ6: 533810 | BK6: Thuỷ An | BL6: Phường An Cựu | BP6: X | BQ6: X | BR6: Bưu điện TT Thuận Hóa - Phú Xuân
A7: 5 | B7: 5310 | C7: Bưu điện TT Thuận Hóa - Phú Xuân | D7: SME | E7: T001799967 | F7: CÔNG TY TNHH MTV PHÁT LÊ | G7: 108 TRƯỜNG CHINH, P. An Đông TP. Huế Tỉnh Thừa Thiên Huế | H7: 0234.3934999 | I7: Trần Thị Thúy Nhi | J7: T001799967 | K7: 3301335118 | L7: 391/HĐBC/BĐTPH-PL | M7: 44168 | N7: Không xác định | O7: Không có | P7: Thanh toán vào tháng sau | Q7: Ngay khi sử dụng dịch vụ Thanh toán tại địa chỉ bên A | S7: Đang hoạt động | T7: HỒ VĂN KỲ | U7: ETN001, CTN001 | W7: Tài liệu | X7: 1.12 | Y7: 0.27 | Z7: 7325.63 | AB7: 533810 | AC7: 533810_dungntt | AD7: SỐ ĐT NTO GHI TRÊN ĐƠN HÀNG.TKS | AE7: Theo quy định TCT | AF7: Không có yêu cầu khác. | AJ7: đã thanh toán | AM7: 108 TRƯỜNG CHINH, P. An Đông TP. Huế Tỉnh Thừa Thiên Huế | AN7: 09h00-11h00; 15h00-17h00 | AO7: 1-2 lần/tuần | AP7: 8 | AQ7: Xe máy | AS7: 45869 | BC7: X | BD7: 334254 | BE7: 226908 | BF7: 179175 | BG7: =SUM(BD7:BF7) -> 740337 | BH7: Hồ sơ vật lý và hồ sơ điện tử | BI7: Phát - Long | BJ7: 533810 | BK7: Thuỷ An | BL7: Phường An Cựu | BP7: X | BQ7: X | BR7: Bưu điện TT Thuận Hóa - Phú Xuân
A8: 6 | B8: 5310 | C8: Bưu điện TT Thuận Hóa - Phú Xuân | D8: SME | E8: C001929335 | F8: Công Ty Tnhh Tm Tân Quốc Hùng | G8: 128 hùng vương, P. Phú Hội TP. Huế Tỉnh Thừa Thiên Huế | H8: 02343811015 | I8: Võ Văn Hùng | J8: C001929335 | K8: 3300556058 | L8: 389/HĐBC | M8: 44228 | N8: Không xác định | O8: Không có | P8: Thanh toán vào tháng sau | S8: Đang hoạt động | T8: PHẠM THỊ THANH UYÊN | U8: ETN001 | X8: 0.05 | Y8: 0.17 | Z8: 2376 | AB8: 533810 | AC8: 533810_dungntt | AD8: SỐ ĐT NTO GHI TRÊN ĐƠN HÀNG.TKS | AE8: Theo quy định TCT | AF8: Không có yêu cầu khác. | AJ8: đã thanh toán | AM8: 128 hùng vương, P. Phú Hội TP. Huế Tỉnh Thừa Thiên Huế | AN8: 09h00-11h00; 15h00-17h00 | AO8: 1-2 lần/tuần | AP8: 5 | AQ8: Xe máy | AS8: 45869 | BC8: X | BD8: 82200 | BE8: 100200 | BF8: 0 | BG8: =SUM(BD8:BF8) -> 182400 | BH8: Hồ sơ vật lý và hồ sơ điện tử | BI8: Phát - Long | BJ8: 533810 | BK8: Thuỷ An | BL8: Phường An Cựu | BP8: X | BQ8: x | BR8: Bưu điện TT Thuận Hóa - Phú Xuân
A9: 7 | B9: 5310 | C9: Bưu điện TT Thuận Hóa - Phú Xuân | D9: SME | E9: T002490015 | F9: Công Ty Cổ Phần Tập Đoàn IUC | G9: Tầng 3, Tòa nhà Vinaconex 7, số 64 Đường Nguyễn Văn Giáp , phường Cầu Diễn, Quận Nam Từ Liêm, Hà Nội | H9: 0908576568 | I9: Nguyễn Thành Công | J9: T002490015 | K9: 0104230537 | L9: 383.2021/HĐBC-BĐTPH-IUC | M9: 44389 | N9: Không xác định | O9: Không có | P9: Thanh toán vào tháng sau | S9: Đang hoạt động | T9: HỒ VĂN KỲ | U9: ETN001 | X9: 0.07 | Y9: 0.1 | Z9: 2008.8 | AB9: 533810 | AC9: 533810_dungntt | AD9: SỐ ĐT NTO GHI TRÊN ĐƠN HÀNG.TKS | AE9: Theo quy định TCT | AF9: Không có yêu cầu khác. | AJ9: đã thanh toán | AM9: Tầng 3, Tòa nhà Vinaconex 7, số 64 Đường Nguyễn Văn Giáp , phường Cầu Diễn, Quận Nam Từ Liêm, Hà Nội | AN9: 09h00-11h00; 15h00-17h00 | AO9: 1-2 lần/tuần | AP9: 3 | AQ9: Xe máy | AS9: 45869 | BC9: X | BD9: 96600 | BE9: 84600 | BF9: 245158 | BG9: =SUM(BD9:BF9) -> 426358 | BH9: Hồ sơ vật lý và hồ sơ điện tử | BI9: Phát - Long | BJ9: 533810 | BK9: Thuỷ An | BL9: Phường An Cựu | BP9: X | BQ9: X | BR9: Bưu điện TT Thuận Hóa - Phú Xuân
A10: 8 | B10: 5310 | C10: Bưu điện TT Thuận Hóa - Phú Xuân | D10: Shop | E10: C005695891 | F10: Lê Thị Mỹ Hiền | G10: 04 Hoàng Văn Thụ, P. Xuân Phú TP. Huế Tỉnh Thừa Thiên Huế | H10: 0775555986 | J10: C005695891 | L10: HĐ170-HĐBC-BĐTP-LTMH | M10: 44890 | N10: Không xác định | O10: Không có | P10: 01 tháng/lần Thanh toán tại địa chỉ bên A | S10: Đang hoạt động | T10: PHẠM THỊ THANH UYÊN | U10: ETN037 | V10: GTG021 | W10: thư | X10: 0.05 | Y10: 0.07 | Z10: 1188 | AB10: 533810 | AC10: 533810_dungntt | AE10: Theo quy định TCT | AF10: Không có yêu cầu khác. | AJ10: đã thanh toán | AM10: 04 Hoàng Văn Thụ, P. Xuân Phú TP. Huế Tỉnh Thừa Thiên Huế | AP10: 2 | AR10: Khách hàng tự mang đến bưu cục | AS10: 45869 | BB10: X | BD10: 51200 | BE10: 1182500 | BF10: 986000 | BG10: =SUM(BD10:BF10) -> 2219700 | BH10: Hồ sơ vật lý và hồ sơ điện tử | BI10: Phát - Long | BJ10: 533810 | BK10: Thuỷ An | BL10: Phường An Cựu | BP10: X | BQ10: X | BR10: Bưu điện TT Thuận Hóa - Phú Xuân
A11: 9 | B11: 5310 | C11: Bưu điện TT Thuận Hóa - Phú Xuân | D11: SME | E11: T001799573 | F11: CTY CP BĐS MINH ĐIỀN VITAL | G11: Khu đô thị The Manor Crown, Xuân Phú, TP huế | H11: 0907024029 | I11: Đặng Mạnh Cường | J11: T001799573 | K11: 3301350500 | L11: HĐ394-HĐBC-BĐTPH-VITAL | M11: 44169 | N11: Không xác định | O11: Không có | P11: Thanh toán vào tháng sau | S11: Đang hoạt động | T11: HỒ VĂN KỲ | U11: ETN001 | X11: 0.06 | Y11: 0.07 | Z11: 820.8 | AB11: 533810 | AC11: 533810_dungntt | AD11: SỐ ĐT NTO GHI TRÊN ĐƠN HÀNG.TKS | AE11: Theo quy định TCT | AF11: Không có yêu cầu khác. | AJ11: 157.464 | AK11: đang làm thanh toán | AM11: Khu đô thị The Manor Crown, Xuân Phú, TP huế | AN11: 09h00-11h00; 15h00-17h00 | AO11: 1-2 lần/tuần | AP11: 2 | AQ11: Xe máy | AS11: 45869 | BC11: X | BD11: 357000 | BE11: 365200 | BF11: 208800 | BG11: =SUM(BD11:BF11) -> 931000 | BH11: Hồ sơ vật lý và hồ sơ điện tử | BI11: Phát - Long | BJ11: 533810 | BK11: Thuỷ An | BL11: Phường An Cựu | BP11: X | BQ11: X | BR11: Bưu điện TT Thuận Hóa - Phú Xuân
A12: 10 | B12: 5310 | C12: Bưu điện TT Thuận Hóa - Phú Xuân | D12: SME | E12: T001399385 | F12: CÔNG TY CỔ PHẦN VẬN TẢI VÀ DỊCH VỤ PETROLIMEX THỪA THIÊN HUẾ | H12: 02343812117 | I12: Chị Trang | J12: T001399385 | L12: 100/HĐBC-BĐTP/CTY PERTOLIMEX | M12: 06/06/2017 | N12: Không xác định | P12: 1 lần/ tháng | S12: Đang hoạt động | T12: PHẠM THỊ THANH UYÊN | U12: ETN013 | W12: TÀI LIỆU | X12: 0.14375 | Y12: 32 | Z12: 32150 | AB12: 533810 | AC12: 533810_dungntt | AD12: BƯU TÁ VUI LÒNG LH SĐT NGƯỜI NHẬN TRÊN BG ĐỂ PHÁT HÀNH | AE12: Theo quy định của TCT | AJ12: 1,983,636 | AK12: đang thanh toán | AM12: 13 Trần Thanh Mại, phường An Cựu | AN12: 14h00-16h00 | AO12: 1 lân / ngày | AP12: 35 | AQ12: Xe máy | AS12: 45862 | AV12: Khi có yêu cầu | BC12: X | BD12: 4097925 | BE12: 1407542 | BF12: 222700 | BG12: =SUM(BD12:BF12) -> 5728167 | BH12: Hồ sơ vật lý và hồ sơ điện tử | BI12: vũ - lan | BJ12: 533810 | BK12: Thuỷ An | BL12: Phường An Cựu | BP12: X | BQ12: X | BR12: Bưu điện TT Thuận Hóa - Phú Xuân
A13: 11 | B13: 5310 | C13: Bưu điện TT Thuận Hóa - Phú Xuân | D13: SME | E13: T001799834 | F13: CÔNG TY CỔ PHẦN XÂY DỰNG VÀ ĐẦU TƯ XUÂN PHÚ | G13: NHÀ 17 ĐƯỜNG SỐ 4 AN CỰU CITY, P. An Cựu TP. Huế Tỉnh Thừa Thiên Huế | H13: 0705358292 | I13: Lê Thanh Hà | J13: T001799834 | K13: 3301545034 | L13: HĐ377-HĐBC-BĐTPH-CTCPVXDĐTXP | M13: 44169 | N13: Không xác định | O13: Không có | P13: Thanh toán trong tháng sau | S13: Đang hoạt động | T13: HỒ VĂN KỲ | U13: ETN001 | X13: 0.58 | Y13: 0.1 | Z13: 5335.2 | AB13: 533810 | AC13: 533810_dungntt | AD13: BƯU TÁ LIÊN HỆ SĐT TRÊN BG ĐỂ PHÁT HÀNG | AE13: Theo quy định TCT | AF13: Không có yêu cầu khác. | AJ13: đã thanh toán | AM13: NHÀ 17 ĐƯỜNG SỐ 4 AN CỰU CITY, P. An Cựu TP. Huế Tỉnh Thừa Thiên Huế | AN13: 14h00-17h00 | AO13: 1-2 lần/tháng | AP13: 3 | AQ13: Xe máy | AS13: 45869 | BC13: X | BD13: 0 | BE13: 9600 | BF13: 37200 | BG13: =SUM(BD13:BF13) -> 46800 | BH13: Hồ sơ vật lý và hồ sơ điện tử | BI13: Bảo + Hương | BJ13: 533810 | BK13: Thuỷ An | BL13: Phường An Cựu | BP13: X | BQ13: x | BR13: Bưu điện TT Thuận Hóa - Phú Xuân
A14: 12 | B14: 5310 | C14: Bưu điện TT Thuận Hóa - Phú Xuân | D14: SME | E14: T001800268 | F14: TRƯỜNG CAO ĐẲNG Y TẾ | G14: 1 NGUYỄN TRƯỜNG TỘ, TP HUẾ | H14: 0234.3822414 | I14: Văn Thư | J14: T001800268 | K14: 3300369717 | L14: 253/2021/HĐBC/BĐTP-CĐYTE | M14: 44272 | N14: Không xác định | P14: 1 lần/ tháng | S14: Đang hoạt động | T14: HỒ VĂN KỲ | U14: ETN001, ETN013 | W14: Tài liệu | X14: 0.04 | Y14: 0.97 | Z14: 18101 | AB14: 533810 | AC14: 533810_dungntt | AD14: BƯU TÁ VUI LÒNG LIÊN HỆ SĐT NGƯỜI NHẬN TRÊN BƯU GỬI ĐỂ PHÁT HÀNG | AE14: Theo quy định của TCT | AJ14: đã thanh toán | AM14: 1 NGUYỄN TRƯỜNG TỘ, TP HUẾ | AN14: 14h-15h | AO14: 1 lần/ ngày | AP14: 29 | AQ14: xe máy | AS14: hằng ngày | AT14: BƯU TÁ VUI LÒNG LIÊN HỆ SĐT NGƯỜI NHẬN TRÊN BƯU GỬI ĐỂ PHÁT HÀNG | AU14: KHÔNG ĐƯỢC CẬP NHẬT KHỐNG TT PHÁT , NHẬP ĐẦY ĐỦ TT NGƯỜI NHẬN , NGƯỜI NHẬN THAY | BC14: X | BD14: 26000 | BE14: 0 | BF14: 0 | BG14: =SUM(BD14:BF14) -> 26000 | BH14: Hồ sơ vật lý và hồ sơ điện tử | BI14: Rà soát để điều chỉnh lại bàn giao trên CMS | BJ14: 533810 | BK14: Thuỷ An | BL14: Phường An Cựu | BP14: X | BQ14: X | BR14: Bưu điện TT Thuận Hóa - Phú Xuân
A15: 13 | B15: 5310 | C15: Bưu điện TT Thuận Hóa - Phú Xuân | D15: Shop | E15: C016607629 | F15: Cánh Buồm | G15: Lô A34 Đường số 2 KĐT An Cựu City, P. An Đông TP. Huế Tỉnh Thừa Thiên Huế | I15: Cánh Buồm | J15: C016607629 | P15: 1 lần/1 tháng | S15: Đang hoạt động | T15: PHẠM THỊ THANH UYÊN | U15: ETN011 | V15: GTG021 | W15: Tài liệu | X15: 0.077638889 | Y15: 2.4 | Z15: 65123.5 | AB15: 533810 | AC15: 533810_dungntt | AE15: Thực hiện theo quy định của TCT | AJ15: Đã thanh toán công nợ | AM15: Lô A34 Đường số 2 KĐT An Cựu City, P. An Đông TP. Huế Tỉnh Thừa Thiên Huế | AN15: 15h00-17h00 | AO15: 1 lần/ngày | AP15: 72 | AQ15: xe máy | AS15: 45856 | BC15: X | BD15: 741025 | BE15: 481435 | BF15: 0 | BG15: =SUM(BD15:BF15) -> 1222460 | BH15: Hồ sơ vật lý và hồ sơ điện tử | BI15: Phát - Long | BJ15: 533810 | BK15: Thuỷ An | BL15: Phường An Cựu | BP15: X | BQ15: R | BR15: Bưu điện TT Thuận Hóa - Phú Xuân
A16: 14 | B16: 5310 | C16: Bưu điện TT Thuận Hóa - Phú Xuân | D16: SME | E16: T005217327 | F16: Công Ty Cổ Phần BWB-chi Nhánh Huế | G16: Tầng 6 tháp The Manor Crown | I16: Tuyết | J16: T005217327 | K16: 0107763981-002 | P16: Thanh toán vào tháng sau | S16: Đang hoạt động | T16: PHẠM THỊ THANH UYÊN | U16: ETN001 | X16: 0.065 | Y16: 0.066666667 | Z16: 1231.2 | AB16: 533810 | AC16: 533810_dungntt | AE16: Theo quy định TCT | AF16: Không có yêu cầu khác. | AJ16: 31.752 | AK16: đang làm thanh toán | AM16: Tầng 6 tháp The Manor Crown | AN16: 09h00-11h00; 15h00-17h00 | AO16: 1-2 lần/tuần | AP16: 2 | AQ16: Xe máy | AS16: 45869 | BC16: X | BD16: 0 | BE16: 18000 | BF16: 0 | BG16: =SUM(BD16:BF16) -> 18000 | BH16: Hồ sơ vật lý và hồ sơ điện tử | BI16: Phát - Long | BJ16: 533810 | BK16: Thuỷ An | BL16: Phường An Cựu | BP16: X | BQ16: R | BR16: Bưu điện TT Thuận Hóa - Phú Xuân
A17: 15 | B17: 5310 | C17: Bưu điện TT Thuận Hóa - Phú Xuân | D17: Cá Nhân | E17: C018726221 | F17: Nguyễn Huyền Tôn Nữ Ái Vân | G17: 08 Tố Hữu, P. Xuân Phú , Quận Thuận Hóa, TP. Huế | H17: 0899489952 | J17: C018726221 | L17: 259.202TH5/HĐBC/BĐKVTHPX-NHTNAV | M17: 45952 | S17: Đang hoạt động | T17: NGUYỄN BÁ TRÀ MI | AB17: 533810 | AC17: 533810_dungntt | BD17: 204518 | BE17: 117295 | BF17: 79036 | BG17: =SUM(BD17:BF17) -> 400849 | BI17: Rà soát để bàn giao trên CMS | BJ17: 533810 | BK17: Thuỷ An | BL17: Phường An Cựu | BM17: X | BP17: X | BQ17: R | BR17: Bưu điện TT Thuận Hóa - Phú Xuân
A18: 16 | B18: 5310 | C18: Bưu điện TT Thuận Hóa - Phú Xuân | D18: Cá Nhân | E18: C018656707 | F18: Nguyễn Ngọc Phú | G18: 189 Bà Triệu - Thuận Hóa - Thành Phố Huế | H18: 0898254999 | J18: C018656707 | S18: Đang hoạt động | T18: NGUYỄN BÁ TRÀ MI | AB18: 533810 | AC18: 533810_dungntt | BD18: 59000 | BE18: 0 | BF18: 0 | BG18: =SUM(BD18:BF18) -> 59000 | BI18: Lan - Thắm | BJ18: 533810 | BK18: Thuỷ An | BL18: Phường An Cựu | BP18: X | BQ18: R | BR18: Bưu điện TT Thuận Hóa - Phú Xuân
A19: 17 | B19: 5310 | C19: Bưu điện TT Thuận Hóa - Phú Xuân | D19: Cá Nhân | E19: C018477419 | F19: Nhà May Duy Tuấn | G19: 134 Trường Chinh - Phường An Cựu - Thành Phố Huế | H19: 0908680906 | J19: C018477419 | T19: NGUYỄN BÁ TRÀ MI | AB19: 533810 | AC19: 533810_dungntt | BD19: 143523 | BE19: 145703 | BF19: 144945 | BG19: =SUM(BD19:BF19) -> 434171 | BI19: Lan - Thắm/Phát - Long | BJ19: 533810 | BK19: Thuỷ An | BL19: Phường An Cựu | BP19: X | BQ19: R | BR19: Bưu điện TT Thuận Hóa - Phú Xuân
A20: 18 | B20: 5310 | C20: Bưu điện TT Thuận Hóa - Phú Xuân | D20: Tổ Chức | E20: T018318911 | F20: CÔNG AN PHƯỜNG AN CỰU | G20: 18 Hoàng Quốc Việt | H20: 02343817234 | J20: T018318911 | L20: HĐ230.2025-HĐBC-PHBC-BĐTP-CAPHUONGANCUU | M20: 45887 | S20: Đang thực hiện | T20: NGUYỄN BÁ TRÀ MI | AB20: 533810 | AC20: 533810_dungntt | BD20: 135200 | BE20: 502345 | BF20: 249172 | BG20: =SUM(BD20:BF20) -> 886717 | BI20: Phát - Long | BJ20: 533810 | BK20: Thuỷ An | BL20: Phường An Cựu | BP20: X | BQ20: R | BR20: Bưu điện TT Thuận Hóa - Phú Xuân
A21: 19 | B21: 5310 | C21: Bưu điện TT Thuận Hóa - Phú Xuân | D21: Cá Nhân | E21: C018568551 | F21: CÔNG TY CỔ PHẦN TẬP ĐOÀN BẢO HIỂM DBV - CN HUẾ | G21: Tầng 2 tòa nhà 189 Phạm Văn Đồng, Phường Vỹ Dạ, Thành Phố Huế | H21: 097258523 | J21: C018568551 | L21: 249.202TH5/HĐBC/BĐKVTHPX-DBV | M21: 45931 | S21: Đang thực hiện | T21: NGUYỄN BÁ TRÀ MI | AB21: 533810 | AC21: 533810_dungntt | BD21: 493600 | BE21: 574300 | BF21: 215000 | BG21: =SUM(BD21:BF21) -> 1282900 | BI21: Rà soát để bàn giao trên CMS | BJ21: 533810 | BK21: Thuỷ An | BL21: Phường An Cựu | BP21: X | BQ21: R | BR21: Bưu điện TT Thuận Hóa - Phú Xuân
A22: 20 | B22: 5310 | C22: Bưu điện TT Thuận Hóa - Phú Xuân | D22: Cá Nhân | E22: C018388055 | F22: Shin shop | G22: phong chương phong điền | H22: 0764768555 | J22: C018388055 | L22: HĐ235.2025_HĐBC-BĐH_HTN | M22: 45908 | S22: Đang thực hiện | T22: NGUYỄN BÁ TRÀ MI | AB22: 533810 | AC22: 533810_dungntt | BD22: 94495 | BE22: 16400 | BF22: 28259 | BG22: =SUM(BD22:BF22) -> 139154 | BI22: Rà soát để bàn giao trên CMS | BJ22: 533810 | BK22: Thuỷ An | BL22: Phường An Cựu | BM22: X | BP22: X | BQ22: R | BR22: Bưu điện TT Thuận Hóa - Phú Xuân
A23: 21 | B23: 5310 | C23: Bưu điện TT Thuận Hóa - Phú Xuân | D23: Cá Nhân | E23: C018272260 | F23: đinh thị phượng | G23: bến xe phía nam phường an cựu | H23: 0814767134 | J23: C018272260 | L23: HĐ232.2025_HĐBC_BĐH_ĐTP | M23: 45887 | S23: Đang thực hiện | T23: NGUYỄN BÁ TRÀ MI | AB23: 533810 | AC23: 533810_dungntt | BD23: 0 | BE23: 601000 | BF23: 0 | BG23: =SUM(BD23:BF23) -> 601000 | BI23: Rà soát để bàn giao trên CMS | BJ23: 533810 | BK23: Thuỷ An | BL23: Phường An Cựu | BP23: X | BQ23: R | BR23: Bưu điện TT Thuận Hóa - Phú Xuân
A24: 22 | B24: 5310 | C24: Bưu điện TT Thuận Hóa - Phú Xuân | D24: Tổ Chức | E24: T018411531 | F24: Phú Xuân Travel | G24: 51 Bà Triệu, Vỹ Dạ, Thành Phố Huế | H24: 0902882168 | J24: T018411531 | L24: 239.2025/HĐBC/BĐKVTHPX-PXT | M24: 45909 | S24: Đang thực hiện | T24: NGUYỄN BÁ TRÀ MI | AB24: 533810 | AC24: 533810_dungntt | BD24: 45100 | BE24: 0 | BF24: 0 | BG24: =SUM(BD24:BF24) -> 45100 | BI24: Lan - Thắm | BJ24: 533810 | BK24: Thuỷ An | BL24: Phường An Cựu | BP24: X | BQ24: R | BR24: Bưu điện TT Thuận Hóa - Phú Xuân
A25: 23 | B25: 5310 | C25: Bưu điện TT Thuận Hóa - Phú Xuân | D25: Cá Nhân | E25: C018894162 | F25: ÁO DÀI ĐAN PHƯƠNG | G25: 08 Đường Bà Triệu, P. Phú Hội, Quận Phú Xuân | H25: 0914478999 | J25: C018894162 | L25: 264.2025/HĐBC/BĐKVTHPX-ADĐP | M25: 45976 | S25: Đang hoạt động | U25: ETN011 | V25: GTG071 | X25: 4373 | Y25: 2 | Z25: 208290 | AB25: 533810 | AC25: 533810_dungntt | AD25: hỗ trợ phát ngay khi đến, cám ơn. | BD25: 801395 | BE25: 694351 | BF25: 448215 | BG25: =SUM(BD25:BF25) -> 1943961 | BH25: Chưa có thông tin | BI25: Rà soát để điều chỉnh lại bàn giao trên CMS | BJ25: 533810 | BK25: Thuỷ An | BL25: Phường An Cựu | BP25: X | BQ25: R | BR25: Bưu điện TT Thuận Hóa - Phú Xuân
A26: 24 | B26: 5310 | C26: Bưu điện TT Thuận Hóa - Phú Xuân | D26: Tổ Chức | E26: T018894468 | F26: Văn Phòng HĐND Và UBND Phường An Cựu | G26: 67A Đường Hoàng Quốc Việt, P. An Cựu, Quận Phú Xuân | J26: T018894468 | L26: 262.2025/HĐBC/BĐKVTHPX-HĐN-UBNDPAC | M26: 45976 | S26: Đang hoạt động | U26: ETN001 | V26: 0 | X26: 120 | Y26: 3 | Z26: 32500 | AB26: 533810 | AC26: 533810_dungntt | AD26: 0 | BD26: 168600 | BE26: 498745 | BF26: 89200 | BG26: =SUM(BD26:BF26) -> 756545 | BI26: Rà soát để bàn giao trên CMS | BJ26: 533810 | BK26: Thuỷ An | BL26: Phường An Cựu | BP26: X | BQ26: R | BR26: Bưu điện TT Thuận Hóa - Phú Xuân
A27: 25 | B27: 5310 | C27: Bưu điện TT Thuận Hóa - Phú Xuân | D27: Cá Nhân | E27: C019136875 | F27: May store | G27: số nhà 18 kiệt 154 bà triệu, Phường Thuận Hóa, TP Huế | H27: 0365156019 | J27: C019136875 | L27: 285/2025/HĐ_BC-PHBC/BĐTP-MAYSTORE | M27: 46023 | S27: Đang hoạt động | T27: NGUYỄN BÁ TRÀ MI | U27: CTN009; CTN007 | V27: GTG021; GTG047;GTG021 | X27: 774.02914 | Y27: 398 | Z27: 8262457 | AB27: 533810 | AC27: 533810_dungntt | AD27: Không cho xem hàng, gọi cho người gửi trước khi chuyển hoàn | BD27: 0 | BE27: 8262457 | BF27: 4628564 | BG27: =SUM(BD27:BF27) -> 12891021 | BI27: Rà soát để bàn giao trên CMS | BJ27: 533810 | BK27: Thuỷ An | BL27: Phường An Cựu | BM27: X | BP27: X | BR27: Bưu điện TT Thuận Hóa - Phú Xuân
A28: 26 | B28: 5310 | C28: Bưu điện TT Thuận Hóa - Phú Xuân | D28: Cá Nhân | E28: C001395300 | F28: Cô Lộc | G28: 4/4/4 Kiệt 33 An Dương Vương An Cựu TP Huế | H28: 0918581215 | J28: C001395300 | L28: 49/HĐBC/BĐTPH-CL | M28: 44256 | S28: Đang hoạt động | T28: PHẠM THỊ THANH UYÊN | U28: CTN001; CTN007 | V28: GTG021; GTG071 | X28: 861.35211 | Y28: 41 | Z28: 1974993 | AB28: 533810 | AC28: 533810_dungntt | AD28: gọi sđt trên đơn hàng | BD28: 0 | BE28: 1974993 | BF28: 848485 | BG28: =SUM(BD28:BF28) -> 2823478 | BI28: Phát - Long | BJ28: 533810 | BK28: Thuỷ An | BL28: Phường An Cựu | BP28: X | BR28: Bưu điện TT Thuận Hóa - Phú Xuân
A29: 27 | B29: 5310 | C29: Bưu điện TT Thuận Hóa - Phú Xuân | D29: Cá Nhân | E29: C019370201 | F29: Võ Nhật Bình | G29: Thôn Bằng Lãng, Thuỷ Bằng, Phường Thủy Xuân, TP Huế | H29: 0867676257 | J29: C019370201 | L29: 01/2026-HĐ/BCCP/BDTPHUE-BDAC-DNB | M29: 46050 | S29: Đang hoạt động | T29: NGUYỄN BÁ TRÀ MI | U29: CTN009 | V29: GTG021 | X29: 1300 | Y29: 5 | Z29: 166668 | AB29: 533810 | AC29: 533810_dungntt | AD29: Hàng dễ vỡ, vui lòng nhẹ tay; Cho xem hàng không cho đụng vào hàng | BD29: 0 | BE29: 166668 | BF29: 277780 | BG29: =SUM(BD29:BF29) -> 444448 | BI29: Rà soát để bàn giao trên CMS | BJ29: 533810 | BK29: Thuỷ An | BL29: Phường An Cựu | BM29: X | BP29: X | BR29: Bưu điện TT Thuận Hóa - Phú Xuân
A30: 28 | B30: 5310 | C30: Bưu điện TT Thuận Hóa - Phú Xuân | D30: Key Account | E30: T017963860 | F30: Trung Tâm HCC Phường An Cựu | G30: 67A Hoàng Quốc Việt, Phường An Cựu, TP Huế | I30: Phan Đăng Phú Khánh | J30: T017963860 | L30: 175/2025/HĐ_BC-PHBC/BĐTT-TTPVHCCPAC | M30: 45839 | N30: Không xác định | O30: Không có | P30: 01 tháng/lần Trong 03 - 05 ngày làm việc tiếp theo kể từ ngày nhận được hoá đơn GTGT hợp lệ | S30: Đang hoạt động | T30: ĐẶNG TUẤN VŨ | U30: Dịch vụ HCC, luân chuyển hồ sơ HCC, KT1, EMS, Chuyển phát bưu phẩm trong nước và quốc tế | W30: Tài liệu | X30: 0.05125 | Y30: 0.4 | Z30: 11000 | AA30: My VNP | AB30: 533810 | AC30: 533810_dungntt | AE30: Thực hiện theo quy định của TCT | AJ30: 356400 | AK30: Đang làm thanh toán | BB30: X | BD30: 1091340 | BE30: 1058397 | BF30: 399441 | BG30: =SUM(BD30:BF30) -> 2549178 | BH30: Hồ sơ vật lý và hồ sơ điện tử | BI30: Lan - Thắm | BJ30: 533810 | BK30: Thuỷ An | BL30: Phường An Cựu | BM30: X | BP30: X | BQ30: X | BR30: Bưu điện TT Thuận Hóa - Phú Xuân
A31: 29 | B31: 5310 | C31: Bưu điện TT Thuận Hóa - Phú Xuân | D31: Tổ Chức | E31: T019531120 | F31: CÔNG TY TNHH DỊCH VỤ SẢN XUẤT PDM VIỆT NAM | G31: 314 Văn Thánh, phường Kim Long, Thành Phố Huế, Việt Nam | J31: T019531120 | L31: 18 /2026/ HĐ¬BC-PHBC/BĐTPHUE-PDM | M31: 46079 | S31: Đang hoạt động | T31: NGUYỄN BÁ TRÀ MI | AB31: 533810 | BD31: 0 | BE31: 0 | BF31: 0 | BG31: =SUM(BD31:BF31) -> 0 | BI31: Rà soát để bàn giao trên CMS | BJ31: 533810 | BK31: Thuỷ An | BL31: Phường An Cựu | BR31: Bưu điện TT Thuận Hóa - Phú Xuân
A32: 30 | B32: 5310 | C32: Bưu điện TT Thuận Hóa - Phú Xuân | D32: Shop | E32: C017177801 | F32: Duyên Trần | G32: xóm 11, X. Phú Mậu H. Phú Vang Tỉnh Thừa Thiên Huế | H32: 0775875875 | I32: Trần Thị Ái Duyên | J32: C017177801 | L32: HĐ56.2025.HĐBC-BĐTTTHPX-DT | M32: 45740 | N32: Không xác định | O32: Không có | P32: Thanh toán vào tháng sau | Q32: Thứ 2,4,6 hàng tuần Chuyển khoản | R32: 0825898192 MBBank Trần Thị Ái Duyên | S32: Đang hoạt động | T32: PHẠM THỊ THANH UYÊN | U32: CTN007, CTN009 | V32: GTG021 | W32: Mỹ phẩm | X32: 0.46 | Y32: 0.57 | Z32: 8420 | AB32: 536790 | AC32: 536790_menpt | AE32: Theo quy định TCT | AF32: Không có yêu cầu khác. | AJ32: Đã thanh toán | AM32: xóm 11, X. Phú Mậu H. Phú Vang Tỉnh Thừa Thiên Huế | AP32: 17 | AR32: Khách hàng tự mang đến bưu cục | AS32: 45869 | BB32: X | BD32: 19000 | BE32: 82834 | BF32: 0 | BG32: =SUM(BD32:BF32) -> 101834 | BH32: Chưa có thông tin | BI32: Bảo + Ni | BJ32: 536790 | BK32: Phú Mậu | BL32: Phường Dương Nỗ | BM32: X | BP32: X | BQ32: X | BR32: Bưu điện TT Thuận Hóa - Phú Xuân
A33: 31 | B33: 5310 | C33: Bưu điện TT Thuận Hóa - Phú Xuân | D33: Shop | E33: C016429937 | F33: Nguyễn Thị Phương Thảo | G33: xóm 11, làng Thanh Tiên, xã Phú Mậu, TP Huế | H33: 0898194881 | J33: C016429937 | L33: HĐ221-HĐBC-BĐTP-NTPT | M33: 45637 | N33: Không xác định | O33: Không có | P33: Trong 03 - 05 ngày làm việc tiếp theo kể từ ngày nhận được hoá đơn GTGT hợp lệ | S33: Đang hoạt động | T33: PHẠM THỊ THANH UYÊN | U33: CTN001, CTN007 | V33: GTG021 | W33: hoa giấy, chông | X33: 1.27 | Y33: 0.2 | Z33: 8039.87 | AB33: 536790 | AC33: 536790_menpt | AE33: Theo quy định TCT | AF33: Không có yêu cầu khác. | AJ33: Đã thanh toán | AM33: xóm 11, làng Thanh Tiên, xã Phú Mậu, TP Huế | AP33: 6 | AR33: Khách hàng tự mang đến bưu cục | AS33: 45869 | BB33: X | BD33: 9237000 | BE33: 5179300 | BF33: 2331600 | BG33: =SUM(BD33:BF33) -> 16747900 | BH33: Hồ sơ vật lý và hồ sơ điện tử | BI33: Bảo + Ni | BJ33: 536790 | BK33: Phú Mậu | BL33: Phường Dương Nỗ | BP33: X | BQ33: X | BR33: Bưu điện TT Thuận Hóa - Phú Xuân
A34: 32 | B34: 5310 | C34: Bưu điện TT Thuận Hóa - Phú Xuân | D34: Shop | E34: C016227458 | F34: Võ Thị Mỹ Phố | G34: kiệt 5 nguyễn hữu cảnh | H34: 0346429532 | I34: Võ Thị Mỹ Phố | J34: C016227458 | L34: HĐ190.2024_HĐBC_BĐTPH-VTMP | M34: 45607 | N34: Không xác định | P34: Thanh toán cước khi chi trả cod | Q34: CK qua ngân hàng (2,4,6 hằng tuần) | R34: 88184868 MB Bank | S34: Đang hoạt động | T34: PHẠM THỊ THANH UYÊN | U34: CTN007 | V34: GTG021 | W34: Ti Giả Avent | X34: 1.5175 | Y34: 0.066666667 | Z34: 1089.3333 | AB34: 536790 | AC34: 536790_menpt | AE34: Theo quy định TCT | AF34: Không có yêu cầu khác. | AJ34: 139512 | AK34: đang làm thanh toán | AM34: kiệt 5 nguyễn hữu cảnh | AN34: 15h00-16h00 | AO34: 2-3 lần/tuần | AP34: 2 | AQ34: Xe máy | AS34: 45869 | BB34: X | BD34: 161807 | BE34: 0 | BF34: 0 | BG34: =SUM(BD34:BF34) -> 161807 | BH34: Hồ sơ vật lý và hồ sơ điện tử | BI34: Rà soát để điều chỉnh lại bàn giao trên CMS | BJ34: 536790 | BK34: Phú Mậu | BL34: Phường Dương Nỗ | BM34: X | BP34: X | BQ34: X | BR34: Bưu điện TT Thuận Hóa - Phú Xuân
A35: 33 | B35: 5310 | C35: Bưu điện TT Thuận Hóa - Phú Xuân | D35: Cá Nhân | E35: C018988315 | F35: Hoài Trinh | G35: Đối diện xóm 6, Mậu Tài, P. Dương Nỗ, Quận Thuận Hóa | H35: 0774507105 | J35: C018988315 | S35: Đang hoạt động | U35: CTN007 | V35: GTG021 | X35: 162300 | Y35: 76 | Z35: 3073500 | AB35: 536790 | AC35: 536790_menpt | AD35: 0 | BD35: 4095235 | BE35: 3533867 | BF35: 665366 | BG35: =SUM(BD35:BF35) -> 8294468 | BI35: Rà soát để bàn giao trên CMS | BJ35: 536790 | BK35: Phú Mậu | BL35: Phường Dương Nỗ | BR35: Bưu điện TT Thuận Hóa - Phú Xuân
A36: 34 | B36: 5310 | C36: Bưu điện TT Thuận Hóa - Phú Xuân | D36: Cá Nhân | E36: C019314788 | F36: Nguyễn Hiếu | G36: Thanh Vinh, phường Dương Nỗ, TP Huế | H36: 0343318436 | J36: C019314788 | L36: HĐ08-2026-HĐBC-BĐKVTHPX- NH | M36: 46042 | S36: Đang hoạt động | T36: HOÀNG VĂN DUY | U36: CTN007; ETN031 | V36: GTG021 | X36: 1606.25 | Y36: 8 | Z36: 4279200 | AB36: 536790 | AC36: 536790_menpt | AD36: 0 | BD36: 0 | BE36: 4279200 | BF36: 371000 | BG36: =SUM(BD36:BF36) -> 4650200 | BI36: Rà soát để bàn giao trên CMS | BJ36: 536790 | BK36: Phú Mậu | BL36: Phường Dương Nỗ | BP36: X | BR36: Bưu điện TT Thuận Hóa - Phú Xuân
A37: 35 | B37: 5310 | C37: Bưu điện TT Thuận Hóa - Phú Xuân | D37: Cá Nhân | E37: C019416597 | F37: nguyễn hữu thảo | G37: kiệt 19, trung đông, phú thượng, tp huế | H37: 0777550775 | J37: C019416597 | L37: C019416597 | M37: 46056 | S37: Đang hoạt động | T37: HOÀNG VĂN DUY | X37: 900 | Y37: 1 | Z37: 36000 | AB37: 536790 | BD37: 0 | BE37: 0 | BF37: 36000 | BG37: =SUM(BD37:BF37) -> 36000 | BI37: Rà soát để bàn giao trên CMS | BJ37: 536790 | BK37: Phú Mậu | BL37: Phường Dương Nỗ | BP37: X | BR37: Bưu điện TT Thuận Hóa - Phú Xuân
A38: 36 | B38: 5310 | C38: Bưu điện TT Thuận Hóa - Phú Xuân | D38: Key Account | E38: T017963459 | F38: Trung Tâm HCC Phường Dương Nỗ | G38: Tổ dân phố Mậu Tài, phường Dương Nỗ, TP. Huế | H38: 0234676722 | I38: Trần Quang Dũng | J38: T017963459 | L38: 172/2025/HĐ_BC-PHBC/BĐTT-TTPVHCCPDN | M38: 45839 | N38: Không xác định | O38: Không có | P38: 01 tháng/lần Trong 03 - 05 ngày làm việc tiếp theo kể từ ngày nhận được hoá đơn GTGT hợp lệ | S38: Đang hoạt động | T38: ĐẶNG TUẤN VŨ | U38: Dịch vụ HCC, luân chuyển hồ sơ HCC, KT1, EMS, Chuyển phát bưu phẩm trong nước và quốc tế | W38: Tài liệu | X38: 0.067714286 | Y38: 0.46666667 | Z38: 12133.333 | AA38: My VNP | AB38: 536790 | AC38: 536790_menpt | AE38: Thực hiện theo quy định của TCT | AJ38: 393120 | AK38: Đang làm thanh toán | BB38: X | BD38: 952200 | BE38: 768500 | BF38: 271500 | BG38: =SUM(BD38:BF38) -> 1992200 | BH38: Hồ sơ vật lý và hồ sơ điện tử | BI38: Bảo + Ni | BJ38: 536790 | BK38: Phú Mậu | BL38: Phường Dương Nỗ | BP38: X | BQ38: X | BR38: Bưu điện TT Thuận Hóa - Phú Xuân
A39: 37 | B39: 5310 | C39: Bưu điện TT Thuận Hóa - Phú Xuân | D39: Tổ Chức | E39: T018859231 | F39: Công An Phường Hoá Châu | G39: TDP Vân Quật Thượng, X. Hương Phong, TX. Hương Trà | H39: 0986244166 | J39: T018859231 | S39: Đang hoạt động | U39: KT1007 | V39: 0 | X39: 210 | Y39: 10 | Z39: 274763 | AB39: 535350 | AC39: 535350_lannh | AD39: 0 | BD39: 557275 | BE39: 572124 | BF39: 185990 | BG39: =SUM(BD39:BF39) -> 1315389 | BH39: Hồ sơ vật lý | BI39: Rà soát để điều chỉnh lại bàn giao trên CMS | BJ39: 535350 | BK39: Hương Vinh | BL39: Phường Hóa Châu | BM39: X | BR39: Bưu điện TT Thuận Hóa - Phú Xuân
A40: 38 | B40: 5310 | C40: Bưu điện TT Thuận Hóa - Phú Xuân | D40: Key Account | E40: T017963122 | F40: UBND Phường Hóa Châu | G40: đường Thanh Hà, TDP Tây Thành, phường Hóa Châu, TP. Huế | I40: Võ Việt Đức | J40: T017963122 | L40: 191/2025/HĐ_BC-PHBC/BĐTT-VPUBHC | M40: 45839 | N40: Không xác định | O40: Không có | P40: 01 tháng/lần Trong 03 - 05 ngày làm việc tiếp theo kể từ ngày nhận được hoá đơn GTGT hợp lệ | S40: Đang hoạt động | T40: ĐẶNG TUẤN VŨ | U40: Dịch vụ HCC, luân chuyển hồ sơ HCC, KT1, EMS, Chuyển phát bưu phẩm trong nước và quốc tế | W40: Tài liệu | X40: 0 | Y40: 0.033333333 | Z40: 0 | AA40: My VNP | AB40: 535350 | AC40: 535350_lannh | AE40: Thực hiện theo quy định của TCT | AJ40: Không có | AK40: Đang làm thanh toán | BB40: X | BD40: 195745 | BE40: 0 | BF40: 0 | BG40: =SUM(BD40:BF40) -> 195745 | BH40: Hồ sơ vật lý và hồ sơ điện tử | BI40: Bảo + Ni | BJ40: 535350 | BK40: Hương Vinh | BL40: Phường Hóa Châu | BP40: X | BQ40: X | BR40: Bưu điện TT Thuận Hóa - Phú Xuân
...

Sheet Sheet1
A1: 1387 | B1: Đơn vị | C1: Tên đơn vị | D1: Loại KHách hàng | E1: Thông tin đơn hàng | V1: Đặc điểm đơn hàng | AK1: Công nợ | AN1: Yêu cầu thu gom | AT1: Lịch sử chăm sóc KHách hàng | AX1: KPI & mục tiêu Đã cam kết | AZ1: Nhóm KHách hàng | BE1: Doanh thu tháng 12/2025 | BF1: Doanh thu tháng 01/2026 | BG1: Doanh thu tháng 02/2026 (01/02-22/02) | BH1: Doanh thu 3 tháng | BI1: THÔNG TIN CHI TIẾT | BJ1: GHI CHÚ | BK1: Mã BC | BL1: Tên BC/VHX | BM1: BĐP/X | BN1: Cước đặc thù | BO1: Người rà soát bàn giao TTKD | BP1: Người rà soát bàn giao TTVH | BQ1: Đơn vị đã gắn HĐ trên CMS | BR1: Đã gửi HĐ vật lý lên TTKD | BS1: Tên đơn vị
A2: TT | E2: Mã CRM/CMS | G2: Tên KHách hàng | H2: Địa chỉ | I2: Điện thoại | J2: Người liên hệ | K2: Mã CRM/CMS | L2: Mã số thuế | M2: Số hợp đồng | N2: Thời hạn hợp đồng | O2: Thời hạn kết thúc | P2: Phụ lục, thoả thuận bổ sung Hợp đồng | Q2: Thời gian, quy định việc thanh toán cước BCCP ghi nợ | R2: Hình thức, thời gian thanh toán tiền thu hộ COD | S2: Số tài KHoản nhận tiền thu hộ COD, phí ship | T2: Trạng thái hoạt động | U2: Người quản lý KHách hàng (Họ tên, số điện thoại, email) | V2: Dịch vụ sử dụng | W2: Dịch vụ GTGT KHác | X2: Nội dung hàng hóa gửi | Y2: KHối lượng dự kiến/bưu gửi | Z2: Sản lượng bình quân/ngày | AA2: Doanh thu bình quân/ngày | AB2: Hình thức phát hành: KH dùng My VNP/exel/thủ công…. | AC2: Bưu cục ghi nhận doanh thu (số hiệu bưu cục, tên bưu cục) | AD2: Tài KHoản trên Portal KHL ghi nhận doanh thu | AE2: Chú dẫn yêu cầu chuyển phát | AF2: Chỉ tiêu thời gian toàn trình dịch vụ | AG2: Yêu cầu KHác: - Gia công, đóng gói - Thuê KHo,... (nếu có) - KHác biệt về thời gian cutoff (nếu có) - ......(nếu có) | AH2: KHiếu nại, chốt phạt bồi thường (KHác biệt nếu có) | AI2: [ ] KHách hàng có cấu hình hệ thống đặc biệt cần duy trì? | AJ2: [ ] Có dịch vụ tuỳ chỉnh hay tích hợp đặc thù? | AK2: [ ] KHách hàng còn công nợ chưa thanh toán? | AL2: [ ] Có lịch trình thu hồi hoặc xử lý công nợ? | AM2: Hình thức phạt đối với chậm trả nợ | AN2: Địa chỉ thu gom (chi tiết đến phường/xã, quận/huyện,..) | AO2: Thời gian thu gom | AP2: Tần suất thu gom | AQ2: Sản lượng thu gom | AR2: Phương tiện thu gom | AS2: KHác biệt thu gom (nếu có) | AT2: [ ] Tương tác gần nhất với KHách hàng | AU2: [ ] Ghi chú yêu cầu đặc biệt hoặc sự cố đang xử lý | AV2: [ ] Cam kết dịch vụ Đã thực hiện | AW2: [ ] Kế hoạch chăm sóc định kỳ | AX2: [ ] Cam kết chất lượng hoặc KPI giữa KHách hàng và Trung tâm Kinh doanh | AY2: [ ] Theo dõi mức độ hoàn thành và kế hoạch tiếp tục | AZ2: KHách hàng sàn TMĐT | BA2: KH tạo đơn bằng phần mềm bán hàng | BB2: KH tạo đơn và gửi thông tin qua API cho BĐVN | BC2: Tạo đơn trên PM MyVNP | BD2: Tạo đơn trên phần mềm Portal KHL | BI2: THÔNG TIN CHI TIẾT
A3: 1 | B3: 5310 | C3: Bưu điện TT Thuận Hóa - Phú Xuân | D3: SME | E3: T004890545 | F3: SME | G3: Công Ty Cổ Phần Toyota Huế | H3: Lô C, KĐT Phú Mỹ An, Đường Tố Hữu, An Đông, TP Huế | I3: 02436299696 | J3: Lê Thế Vỹ | K3: T004890545 | L3: 3301635376 | M3: HĐ54-2022_HĐBC_BĐTPH-MTL | N3: 01/5/2022 | O3: Không xác định | Q3: 1-2 lần/tháng | T3: Đang hoạt động | U3: HỒ VĂN KỲ | V3: ETN001 | X3: Thư | Y3: 17.14 | Z3: 2 | AA3: 51292 | AC3: 533810 | AD3: 533810_dungntt | AF3: Thực hiện theo quy định của TCT | AK3: 3181837 | AL3: Đang liên hệ thanh toán | AN3: Lô C, KĐT Phú Mỹ An, Đường Tố Hữu, An Đông, TP Huế | AO3: 14h00-17h00 | AP3: 1 lần/ngày | AQ3: 66 | AR3: xe máy | AT3: 45855 | BC3: X | BE3: 1862866 | BF3: 2425140 | BG3: 813058 | BH3: 5101064 | BI3: Hồ sơ vật lý và hồ sơ điện tử | BJ3: Phát - Long | BK3: 533810 | BL3: Thuỷ An | BM3: Phường An Cựu | BQ3: X | BR3: X | BS3: Bưu điện TT Thuận Hóa - Phú Xuân
A4: 2 | B4: 5310 | C4: Bưu điện TT Thuận Hóa - Phú Xuân | D4: Shop | E4: C001395675 | F4: Shop | G4: VÕ HOÀNG MINH | H4: Đường số 7, An Cựu City, P An Đông, TP Huế | I4: 0932436536 | J4: VÕ HOÀNG MINH | K4: C001395675 | M4: 151/HĐBC-BĐTP/VHM | N4: 43685 | O4: Không xác định | Q4: Thanh toán ngay khi gửi | T4: Đang hoạt động | U4: PHẠM THỊ THANH UYÊN | V4: ETN011 | X4: TRANH VE | Y4: 3.5743333 | Z4: 0.1 | AA4: 6994.4 | AC4: 533810 | AD4: 533810_dungntt | AF4: Theo quy định TCT | AG4: Không có yêu cầu khác. | AK4: đã thanh toán | AN4: Đường số 7, An Cựu City, P An Đông, TP Huế | AO4: 09h00-11h00; 15h00-17h00 | AP4: 1-2 lần/tuần | AQ4: 3 | AR4: Xe máy | AT4: 45782 | BC4: X | BE4: 232290 | BF4: 175356 | BG4: 0 | BH4: 407646 | BI4: Hồ sơ vật lý và hồ sơ điện tử | BJ4: Phát - Long | BK4: 533810 | BL4: Thuỷ An | BM4: Phường An Cựu | BQ4: X | BR4: X | BS4: Bưu điện TT Thuận Hóa - Phú Xuân
A5: 3 | B5: 5310 | C5: Bưu điện TT Thuận Hóa - Phú Xuân | D5: SME | E5: T001799661 | F5: SME | G5: CÔNG TY TNHH TM QUỐC HÙNG | H5: 86 HÙNG VƯƠNG, TP HUẾ | I5: 0989020237 | J5: Nguyễn Trần Như Ý | K5: T001799661 | L5: 3300338476 | M5: 384/HĐBC/BĐTPH-CTQUOCHUNG | N5: 44169 | O5: Không xác định | P5: Không có | Q5: 01 tháng/lần Thanh toán tại địa chỉ bên A | T5: Đang hoạt động | U5: HỒ VĂN KỲ | V5: ETN011, ETN011 | X5: Phụ tùng xe máy | Y5: 0.41 | Z5: 0.33 | AA5: 13125.6 | AC5: 533810 | AE5: SỐ ĐT NTO GHI TRÊN ĐƠN HÀNG.TSK | AF5: Theo quy định TCT | AG5: Không có yêu cầu khác. | AK5: 759.888 | AL5: đang thanh toán | AN5: 86 HÙNG VƯƠNG, TP HUẾ | AO5: 09h00-11h00; 15h00-17h00 | AP5: 1-2 lần/tuần | AQ5: 10 | AR5: Xe máy | AT5: 45869 | BD5: X | BE5: 0 | BF5: 0 | BG5: 18000 | BH5: 18000 | BI5: Hồ sơ vật lý và hồ sơ điện tử | BJ5: Phát - Long | BK5: 533810 | BL5: Thuỷ An | BM5: Phường An Cựu | BQ5: X | BR5: X | BS5: Bưu điện TT Thuận Hóa - Phú Xuân
A6: 4 | B6: 5310 | C6: Bưu điện TT Thuận Hóa - Phú Xuân | D6: SME | E6: T001456556 | F6: SME | G6: Công ty luật TNHH Nhật Nam và cộng sự | H6: 52 Hoàng Văn Thụ, P An Đông, TP Huế | I6: 0234.3936155 | J6: Trần Nhật Nam | K6: T001456556 | L6: 3301516202 | M6: 149/HĐBC-BĐTP/TNN | N6: 43685 | O6: Không xác định | P6: Không có | Q6: Thanh toán vào tháng sau | T6: Đang hoạt động | U6: PHẠM THỊ THANH UYÊN | V6: ETN001 | Y6: 0.07 | Z6: 0.87 | AA6: 12283.2 | AC6: 533810 | AD6: 533810_dungntt | AE6: SỐ ĐT NTO GHI TRÊN ĐƠN HÀNG.TKS | AF6: Theo quy định TCT | AG6: Không có yêu cầu khác. | AK6: 2,605,824 | AL6: khách hàng chậm trả | AN6: 52 Hoàng Văn Thụ, P An Đông, TP Huế | AO6: 09h00-11h00; 15h00-17h00 | AP6: 1-2 lần/tuần | AQ6: 26 | AR6: Xe máy | AT6: 45869 | BD6: X | BE6: 459600 | BF6: 223200 | BG6: 138400 | BH6: 821200 | BI6: Hồ sơ vật lý và hồ sơ điện tử | BJ6: Phát - Long | BK6: 533810 | BL6: Thuỷ An | BM6: Phường An Cựu | BQ6: X | BR6: X | BS6: Bưu điện TT Thuận Hóa - Phú Xuân
A7: 5 | B7: 5310 | C7: Bưu điện TT Thuận Hóa - Phú Xuân | D7: SME | E7: T001799967 | F7: SME | G7: CÔNG TY TNHH MTV PHÁT LÊ | H7: 108 TRƯỜNG CHINH, P. An Đông TP. Huế Tỉnh Thừa Thiên Huế | I7: 0234.3934999 | J7: Trần Thị Thúy Nhi | K7: T001799967 | L7: 3301335118 | M7: 391/HĐBC/BĐTPH-PL | N7: 44168 | O7: Không xác định | P7: Không có | Q7: Thanh toán vào tháng sau | R7: Ngay khi sử dụng dịch vụ Thanh toán tại địa chỉ bên A | T7: Đang hoạt động | U7: HỒ VĂN KỲ | V7: ETN001, CTN001 | X7: Tài liệu | Y7: 1.12 | Z7: 0.27 | AA7: 7325.63 | AC7: 533810 | AD7: 533810_dungntt | AE7: SỐ ĐT NTO GHI TRÊN ĐƠN HÀNG.TKS | AF7: Theo quy định TCT | AG7: Không có yêu cầu khác. | AK7: đã thanh toán | AN7: 108 TRƯỜNG CHINH, P. An Đông TP. Huế Tỉnh Thừa Thiên Huế | AO7: 09h00-11h00; 15h00-17h00 | AP7: 1-2 lần/tuần | AQ7: 8 | AR7: Xe máy | AT7: 45869 | BD7: X | BE7: 334254 | BF7: 226908 | BG7: 179175 | BH7: 740337 | BI7: Hồ sơ vật lý và hồ sơ điện tử | BJ7: Phát - Long | BK7: 533810 | BL7: Thuỷ An | BM7: Phường An Cựu | BQ7: X | BR7: X | BS7: Bưu điện TT Thuận Hóa - Phú Xuân
A8: 6 | B8: 5310 | C8: Bưu điện TT Thuận Hóa - Phú Xuân | D8: SME | E8: C001929335 | F8: SME | G8: Công Ty Tnhh Tm Tân Quốc Hùng | H8: 128 hùng vương, P. Phú Hội TP. Huế Tỉnh Thừa Thiên Huế | I8: 02343811015 | J8: Võ Văn Hùng | K8: C001929335 | L8: 3300556058 | M8: 389/HĐBC | N8: 44228 | O8: Không xác định | P8: Không có | Q8: Thanh toán vào tháng sau | T8: Đang hoạt động | U8: PHẠM THỊ THANH UYÊN | V8: ETN001 | Y8: 0.05 | Z8: 0.17 | AA8: 2376 | AC8: 533810 | AD8: 533810_dungntt | AE8: SỐ ĐT NTO GHI TRÊN ĐƠN HÀNG.TKS | AF8: Theo quy định TCT | AG8: Không có yêu cầu khác. | AK8: đã thanh toán | AN8: 128 hùng vương, P. Phú Hội TP. Huế Tỉnh Thừa Thiên Huế | AO8: 09h00-11h00; 15h00-17h00 | AP8: 1-2 lần/tuần | AQ8: 5 | AR8: Xe máy | AT8: 45869 | BD8: X | BE8: 82200 | BF8: 100200 | BG8: 0 | BH8: 182400 | BI8: Hồ sơ vật lý và hồ sơ điện tử | BJ8: Phát - Long | BK8: 533810 | BL8: Thuỷ An | BM8: Phường An Cựu | BQ8: X | BR8: x | BS8: Bưu điện TT Thuận Hóa - Phú Xuân
A9: 7 | B9: 5310 | C9: Bưu điện TT Thuận Hóa - Phú Xuân | D9: SME | E9: T002490015 | F9: SME | G9: Công Ty Cổ Phần Tập Đoàn IUC | H9: Tầng 3, Tòa nhà Vinaconex 7, số 64 Đường Nguyễn Văn Giáp , phường Cầu Diễn, Quận Nam Từ Liêm, Hà Nội | I9: 0908576568 | J9: Nguyễn Thành Công | K9: T002490015 | L9: 0104230537 | M9: 383.2021/HĐBC-BĐTPH-IUC | N9: 44389 | O9: Không xác định | P9: Không có | Q9: Thanh toán vào tháng sau | T9: Đang hoạt động | U9: HỒ VĂN KỲ | V9: ETN001 | Y9: 0.07 | Z9: 0.1 | AA9: 2008.8 | AC9: 533810 | AD9: 533810_dungntt | AE9: SỐ ĐT NTO GHI TRÊN ĐƠN HÀNG.TKS | AF9: Theo quy định TCT | AG9: Không có yêu cầu khác. | AK9: đã thanh toán | AN9: Tầng 3, Tòa nhà Vinaconex 7, số 64 Đường Nguyễn Văn Giáp , phường Cầu Diễn, Quận Nam Từ Liêm, Hà Nội | AO9: 09h00-11h00; 15h00-17h00 | AP9: 1-2 lần/tuần | AQ9: 3 | AR9: Xe máy | AT9: 45869 | BD9: X | BE9: 96600 | BF9: 84600 | BG9: 245158 | BH9: 426358 | BI9: Hồ sơ vật lý và hồ sơ điện tử | BJ9: Phát - Long | BK9: 533810 | BL9: Thuỷ An | BM9: Phường An Cựu | BQ9: X | BR9: X | BS9: Bưu điện TT Thuận Hóa - Phú Xuân
A10: 8 | B10: 5310 | C10: Bưu điện TT Thuận Hóa - Phú Xuân | D10: Shop | E10: C005695891 | F10: Shop | G10: Lê Thị Mỹ Hiền | H10: 04 Hoàng Văn Thụ, P. Xuân Phú TP. Huế Tỉnh Thừa Thiên Huế | I10: 0775555986 | K10: C005695891 | M10: HĐ170-HĐBC-BĐTP-LTMH | N10: 44890 | O10: Không xác định | P10: Không có | Q10: 01 tháng/lần Thanh toán tại địa chỉ bên A | T10: Đang hoạt động | U10: PHẠM THỊ THANH UYÊN | V10: ETN037 | W10: GTG021 | X10: thư | Y10: 0.05 | Z10: 0.07 | AA10: 1188 | AC10: 533810 | AD10: 533810_dungntt | AF10: Theo quy định TCT | AG10: Không có yêu cầu khác. | AK10: đã thanh toán | AN10: 04 Hoàng Văn Thụ, P. Xuân Phú TP. Huế Tỉnh Thừa Thiên Huế | AQ10: 2 | AS10: Khách hàng tự mang đến bưu cục | AT10: 45869 | BC10: X | BE10: 51200 | BF10: 1182500 | BG10: 986000 | BH10: 2219700 | BI10: Hồ sơ vật lý và hồ sơ điện tử | BJ10: Phát - Long | BK10: 533810 | BL10: Thuỷ An | BM10: Phường An Cựu | BQ10: X | BR10: X | BS10: Bưu điện TT Thuận Hóa - Phú Xuân
A11: 9 | B11: 5310 | C11: Bưu điện TT Thuận Hóa - Phú Xuân | D11: SME | E11: T001799573 | F11: SME | G11: CTY CP BĐS MINH ĐIỀN VITAL | H11: Khu đô thị The Manor Crown, Xuân Phú, TP huế | I11: 0907024029 | J11: Đặng Mạnh Cường | K11: T001799573 | L11: 3301350500 | M11: HĐ394-HĐBC-BĐTPH-VITAL | N11: 44169 | O11: Không xác định | P11: Không có | Q11: Thanh toán vào tháng sau | T11: Đang hoạt động | U11: HỒ VĂN KỲ | V11: ETN001 | Y11: 0.06 | Z11: 0.07 | AA11: 820.8 | AC11: 533810 | AD11: 533810_dungntt | AE11: SỐ ĐT NTO GHI TRÊN ĐƠN HÀNG.TKS | AF11: Theo quy định TCT | AG11: Không có yêu cầu khác. | AK11: 157.464 | AL11: đang làm thanh toán | AN11: Khu đô thị The Manor Crown, Xuân Phú, TP huế | AO11: 09h00-11h00; 15h00-17h00 | AP11: 1-2 lần/tuần | AQ11: 2 | AR11: Xe máy | AT11: 45869 | BD11: X | BE11: 357000 | BF11: 365200 | BG11: 208800 | BH11: 931000 | BI11: Hồ sơ vật lý và hồ sơ điện tử | BJ11: Phát - Long | BK11: 533810 | BL11: Thuỷ An | BM11: Phường An Cựu | BQ11: X | BR11: X | BS11: Bưu điện TT Thuận Hóa - Phú Xuân
A12: 10 | B12: 5310 | C12: Bưu điện TT Thuận Hóa - Phú Xuân | D12: SME | E12: T001399385 | F12: SME | G12: CÔNG TY CỔ PHẦN VẬN TẢI VÀ DỊCH VỤ PETROLIMEX THỪA THIÊN HUẾ | I12: 02343812117 | J12: Chị Trang | K12: T001399385 | M12: 100/HĐBC-BĐTP/CTY PERTOLIMEX | N12: 06/06/2017 | O12: Không xác định | Q12: 1 lần/ tháng | T12: Đang hoạt động | U12: PHẠM THỊ THANH UYÊN | V12: ETN013 | X12: TÀI LIỆU | Y12: 0.14375 | Z12: 32 | AA12: 32150 | AC12: 533810 | AD12: 533810_dungntt | AE12: BƯU TÁ VUI LÒNG LH SĐT NGƯỜI NHẬN TRÊN BG ĐỂ PHÁT HÀNH | AF12: Theo quy định của TCT | AK12: 1,983,636 | AL12: đang thanh toán | AN12: 13 Trần Thanh Mại, phường An Cựu | AO12: 14h00-16h00 | AP12: 1 lân / ngày | AQ12: 35 | AR12: Xe máy | AT12: 45862 | AW12: Khi có yêu cầu | BD12: X | BE12: 4097925 | BF12: 1407542 | BG12: 222700 | BH12: 5728167 | BI12: Hồ sơ vật lý và hồ sơ điện tử | BJ12: vũ - lan | BK12: 533810 | BL12: Thuỷ An | BM12: Phường An Cựu | BQ12: X | BR12: X | BS12: Bưu điện TT Thuận Hóa - Phú Xuân
A13: 11 | B13: 5310 | C13: Bưu điện TT Thuận Hóa - Phú Xuân | D13: SME | E13: T001799834 | F13: SME | G13: CÔNG TY CỔ PHẦN XÂY DỰNG VÀ ĐẦU TƯ XUÂN PHÚ | H13: NHÀ 17 ĐƯỜNG SỐ 4 AN CỰU CITY, P. An Cựu TP. Huế Tỉnh Thừa Thiên Huế | I13: 0705358292 | J13: Lê Thanh Hà | K13: T001799834 | L13: 3301545034 | M13: HĐ377-HĐBC-BĐTPH-CTCPVXDĐTXP | N13: 44169 | O13: Không xác định | P13: Không có | Q13: Thanh toán trong tháng sau | T13: Đang hoạt động | U13: HỒ VĂN KỲ | V13: ETN001 | Y13: 0.58 | Z13: 0.1 | AA13: 5335.2 | AC13: 533810 | AD13: 533810_dungntt | AE13: BƯU TÁ LIÊN HỆ SĐT TRÊN BG ĐỂ PHÁT HÀNG | AF13: Theo quy định TCT | AG13: Không có yêu cầu khác. | AK13: đã thanh toán | AN13: NHÀ 17 ĐƯỜNG SỐ 4 AN CỰU CITY, P. An Cựu TP. Huế Tỉnh Thừa Thiên Huế | AO13: 14h00-17h00 | AP13: 1-2 lần/tháng | AQ13: 3 | AR13: Xe máy | AT13: 45869 | BD13: X | BE13: 0 | BF13: 9600 | BG13: 37200 | BH13: 46800 | BI13: Hồ sơ vật lý và hồ sơ điện tử | BJ13: Bảo + Hương | BK13: 533810 | BL13: Thuỷ An | BM13: Phường An Cựu | BQ13: X | BR13: x | BS13: Bưu điện TT Thuận Hóa - Phú Xuân
A14: 12 | B14: 5310 | C14: Bưu điện TT Thuận Hóa - Phú Xuân | D14: SME | E14: T001800268 | F14: SME | G14: TRƯỜNG CAO ĐẲNG Y TẾ | H14: 1 NGUYỄN TRƯỜNG TỘ, TP HUẾ | I14: 0234.3822414 | J14: Văn Thư | K14: T001800268 | L14: 3300369717 | M14: 253/2021/HĐBC/BĐTP-CĐYTE | N14: 44272 | O14: Không xác định | Q14: 1 lần/ tháng | T14: Đang hoạt động | U14: HỒ VĂN KỲ | V14: ETN001, ETN013 | X14: Tài liệu | Y14: 0.04 | Z14: 0.97 | AA14: 18101 | AC14: 533810 | AD14: 533810_dungntt | AE14: BƯU TÁ VUI LÒNG LIÊN HỆ SĐT NGƯỜI NHẬN TRÊN BƯU GỬI ĐỂ PHÁT HÀNG | AF14: Theo quy định của TCT | AK14: đã thanh toán | AN14: 1 NGUYỄN TRƯỜNG TỘ, TP HUẾ | AO14: 14h-15h | AP14: 1 lần/ ngày | AQ14: 29 | AR14: xe máy | AT14: hằng ngày | AU14: BƯU TÁ VUI LÒNG LIÊN HỆ SĐT NGƯỜI NHẬN TRÊN BƯU GỬI ĐỂ PHÁT HÀNG | AV14: KHÔNG ĐƯỢC CẬP NHẬT KHỐNG TT PHÁT , NHẬP ĐẦY ĐỦ TT NGƯỜI NHẬN , NGƯỜI NHẬN THAY | BD14: X | BE14: 26000 | BF14: 0 | BG14: 0 | BH14: 26000 | BI14: Hồ sơ vật lý và hồ sơ điện tử | BJ14: Rà soát để điều chỉnh lại bàn giao trên CMS | BK14: 533810 | BL14: Thuỷ An | BM14: Phường An Cựu | BQ14: X | BR14: X | BS14: Bưu điện TT Thuận Hóa - Phú Xuân
A15: 13 | B15: 5310 | C15: Bưu điện TT Thuận Hóa - Phú Xuân | D15: Shop | E15: C016607629 | F15: Shop | G15: Cánh Buồm | H15: Lô A34 Đường số 2 KĐT An Cựu City, P. An Đông TP. Huế Tỉnh Thừa Thiên Huế | J15: Cánh Buồm | K15: C016607629 | Q15: 1 lần/1 tháng | T15: Đang hoạt động | U15: PHẠM THỊ THANH UYÊN | V15: ETN011 | W15: GTG021 | X15: Tài liệu | Y15: 0.077638889 | Z15: 2.4 | AA15: 65123.5 | AC15: 533810 | AD15: 533810_dungntt | AF15: Thực hiện theo quy định của TCT | AK15: Đã thanh toán công nợ | AN15: Lô A34 Đường số 2 KĐT An Cựu City, P. An Đông TP. Huế Tỉnh Thừa Thiên Huế | AO15: 15h00-17h00 | AP15: 1 lần/ngày | AQ15: 72 | AR15: xe máy | AT15: 45856 | BD15: X | BE15: 741025 | BF15: 481435 | BG15: 0 | BH15: 1222460 | BI15: Hồ sơ vật lý và hồ sơ điện tử | BJ15: Phát - Long | BK15: 533810 | BL15: Thuỷ An | BM15: Phường An Cựu | BQ15: X | BR15: R | BS15: Bưu điện TT Thuận Hóa - Phú Xuân
A16: 14 | B16: 5310 | C16: Bưu điện TT Thuận Hóa - Phú Xuân | D16: SME | E16: T005217327 | F16: SME | G16: Công Ty Cổ Phần BWB-chi Nhánh Huế | H16: Tầng 6 tháp The Manor Crown | J16: Tuyết | K16: T005217327 | L16: 0107763981-002 | Q16: Thanh toán vào tháng sau | T16: Đang hoạt động | U16: PHẠM THỊ THANH UYÊN | V16: ETN001 | Y16: 0.065 | Z16: 0.066666667 | AA16: 1231.2 | AC16: 533810 | AD16: 533810_dungntt | AF16: Theo quy định TCT | AG16: Không có yêu cầu khác. | AK16: 31.752 | AL16: đang làm thanh toán | AN16: Tầng 6 tháp The Manor Crown | AO16: 09h00-11h00; 15h00-17h00 | AP16: 1-2 lần/tuần | AQ16: 2 | AR16: Xe máy | AT16: 45869 | BD16: X | BE16: 0 | BF16: 18000 | BG16: 0 | BH16: 18000 | BI16: Hồ sơ vật lý và hồ sơ điện tử | BJ16: Phát - Long | BK16: 533810 | BL16: Thuỷ An | BM16: Phường An Cựu | BQ16: X | BR16: R | BS16: Bưu điện TT Thuận Hóa - Phú Xuân
A17: 15 | B17: 5310 | C17: Bưu điện TT Thuận Hóa - Phú Xuân | D17: Cá Nhân | E17: C018726221 | F17: Cá Nhân | G17: Nguyễn Huyền Tôn Nữ Ái Vân | H17: 08 Tố Hữu, P. Xuân Phú , Quận Thuận Hóa, TP. Huế | I17: 0899489952 | K17: C018726221 | M17: 259.202TH5/HĐBC/BĐKVTHPX-NHTNAV | N17: 45952 | T17: Đang hoạt động | U17: NGUYỄN BÁ TRÀ MI | AC17: 533810 | AD17: 533810_dungntt | BE17: 204518 | BF17: 117295 | BG17: 79036 | BH17: 400849 | BJ17: Rà soát để bàn giao trên CMS | BK17: 533810 | BL17: Thuỷ An | BM17: Phường An Cựu | BN17: X | BQ17: X | BR17: R | BS17: Bưu điện TT Thuận Hóa - Phú Xuân
A18: 16 | B18: 5310 | C18: Bưu điện TT Thuận Hóa - Phú Xuân | D18: Cá Nhân | E18: C018656707 | F18: Cá Nhân | G18: Nguyễn Ngọc Phú | H18: 189 Bà Triệu - Thuận Hóa - Thành Phố Huế | I18: 0898254999 | K18: C018656707 | T18: Đang hoạt động | U18: NGUYỄN BÁ TRÀ MI | AC18: 533810 | AD18: 533810_dungntt | BE18: 59000 | BF18: 0 | BG18: 0 | BH18: 59000 | BJ18: Lan - Thắm | BK18: 533810 | BL18: Thuỷ An | BM18: Phường An Cựu | BQ18: X | BR18: R | BS18: Bưu điện TT Thuận Hóa - Phú Xuân
A19: 17 | B19: 5310 | C19: Bưu điện TT Thuận Hóa - Phú Xuân | D19: Cá Nhân | E19: C018477419 | F19: Cá Nhân | G19: Nhà May Duy Tuấn | H19: 134 Trường Chinh - Phường An Cựu - Thành Phố Huế | I19: 0908680906 | K19: C018477419 | U19: NGUYỄN BÁ TRÀ MI | AC19: 533810 | AD19: 533810_dungntt | BE19: 143523 | BF19: 145703 | BG19: 144945 | BH19: 434171 | BJ19: Lan - Thắm/Phát - Long | BK19: 533810 | BL19: Thuỷ An | BM19: Phường An Cựu | BQ19: X | BR19: R | BS19: Bưu điện TT Thuận Hóa - Phú Xuân
A20: 18 | B20: 5310 | C20: Bưu điện TT Thuận Hóa - Phú Xuân | D20: Tổ Chức | E20: T018318911 | F20: Tổ Chức | G20: CÔNG AN PHƯỜNG AN CỰU | H20: 18 Hoàng Quốc Việt | I20: 02343817234 | K20: T018318911 | M20: HĐ230.2025-HĐBC-PHBC-BĐTP-CAPHUONGANCUU | N20: 45887 | T20: Đang thực hiện | U20: NGUYỄN BÁ TRÀ MI | AC20: 533810 | AD20: 533810_dungntt | BE20: 135200 | BF20: 502345 | BG20: 249172 | BH20: 886717 | BJ20: Phát - Long | BK20: 533810 | BL20: Thuỷ An | BM20: Phường An Cựu | BQ20: X | BR20: R | BS20: Bưu điện TT Thuận Hóa - Phú Xuân
A21: 19 | B21: 5310 | C21: Bưu điện TT Thuận Hóa - Phú Xuân | D21: Cá Nhân | E21: C018568551 | F21: Cá Nhân | G21: CÔNG TY CỔ PHẦN TẬP ĐOÀN BẢO HIỂM DBV - CN HUẾ | H21: Tầng 2 tòa nhà 189 Phạm Văn Đồng, Phường Vỹ Dạ, Thành Phố Huế | I21: 097258523 | K21: C018568551 | M21: 249.202TH5/HĐBC/BĐKVTHPX-DBV | N21: 45931 | T21: Đang thực hiện | U21: NGUYỄN BÁ TRÀ MI | AC21: 533810 | AD21: 533810_dungntt | BE21: 493600 | BF21: 574300 | BG21: 215000 | BH21: 1282900 | BJ21: Rà soát để bàn giao trên CMS | BK21: 533810 | BL21: Thuỷ An | BM21: Phường An Cựu | BQ21: X | BR21: R | BS21: Bưu điện TT Thuận Hóa - Phú Xuân
A22: 20 | B22: 5310 | C22: Bưu điện TT Thuận Hóa - Phú Xuân | D22: Cá Nhân | E22: C018388055 | F22: Cá Nhân | G22: Shin shop | H22: phong chương phong điền | I22: 0764768555 | K22: C018388055 | M22: HĐ235.2025_HĐBC-BĐH_HTN | N22: 45908 | T22: Đang thực hiện | U22: NGUYỄN BÁ TRÀ MI | AC22: 533810 | AD22: 533810_dungntt | BE22: 94495 | BF22: 16400 | BG22: 28259 | BH22: 139154 | BJ22: Rà soát để bàn giao trên CMS | BK22: 533810 | BL22: Thuỷ An | BM22: Phường An Cựu | BN22: X | BQ22: X | BR22: R | BS22: Bưu điện TT Thuận Hóa - Phú Xuân
A23: 21 | B23: 5310 | C23: Bưu điện TT Thuận Hóa - Phú Xuân | D23: Cá Nhân | E23: C018272260 | F23: Cá Nhân | G23: đinh thị phượng | H23: bến xe phía nam phường an cựu | I23: 0814767134 | K23: C018272260 | M23: HĐ232.2025_HĐBC_BĐH_ĐTP | N23: 45887 | T23: Đang thực hiện | U23: NGUYỄN BÁ TRÀ MI | AC23: 533810 | AD23: 533810_dungntt | BE23: 0 | BF23: 601000 | BG23: 0 | BH23: 601000 | BJ23: Rà soát để bàn giao trên CMS | BK23: 533810 | BL23: Thuỷ An | BM23: Phường An Cựu | BQ23: X | BR23: R | BS23: Bưu điện TT Thuận Hóa - Phú Xuân
A24: 22 | B24: 5310 | C24: Bưu điện TT Thuận Hóa - Phú Xuân | D24: Tổ Chức | E24: T018411531 | F24: Tổ Chức | G24: Phú Xuân Travel | H24: 51 Bà Triệu, Vỹ Dạ, Thành Phố Huế | I24: 0902882168 | K24: T018411531 | M24: 239.2025/HĐBC/BĐKVTHPX-PXT | N24: 45909 | T24: Đang thực hiện | U24: NGUYỄN BÁ TRÀ MI | AC24: 533810 | AD24: 533810_dungntt | BE24: 45100 | BF24: 0 | BG24: 0 | BH24: 45100 | BJ24: Lan - Thắm | BK24: 533810 | BL24: Thuỷ An | BM24: Phường An Cựu | BQ24: X | BR24: R | BS24: Bưu điện TT Thuận Hóa - Phú Xuân
A25: 23 | B25: 5310 | C25: Bưu điện TT Thuận Hóa - Phú Xuân | D25: Cá Nhân | E25: C018894162 | F25: Cá Nhân | G25: ÁO DÀI ĐAN PHƯƠNG | H25: 08 Đường Bà Triệu, P. Phú Hội, Quận Phú Xuân | I25: 0914478999 | K25: C018894162 | M25: 264.2025/HĐBC/BĐKVTHPX-ADĐP | N25: 45976 | T25: Đang hoạt động | V25: ETN011 | W25: GTG071 | Y25: 4373 | Z25: 2 | AA25: 208290 | AC25: 533810 | AD25: 533810_dungntt | AE25: hỗ trợ phát ngay khi đến, cám ơn. | BE25: 801395 | BF25: 694351 | BG25: 448215 | BH25: 1943961 | BI25: Chưa có thông tin | BJ25: Rà soát để điều chỉnh lại bàn giao trên CMS | BK25: 533810 | BL25: Thuỷ An | BM25: Phường An Cựu | BQ25: X | BR25: R | BS25: Bưu điện TT Thuận Hóa - Phú Xuân
A26: 24 | B26: 5310 | C26: Bưu điện TT Thuận Hóa - Phú Xuân | D26: Tổ Chức | E26: T018894468 | F26: Tổ Chức | G26: Văn Phòng HĐND Và UBND Phường An Cựu | H26: 67A Đường Hoàng Quốc Việt, P. An Cựu, Quận Phú Xuân | K26: T018894468 | M26: 262.2025/HĐBC/BĐKVTHPX-HĐN-UBNDPAC | N26: 45976 | T26: Đang hoạt động | V26: ETN001 | W26: 0 | Y26: 120 | Z26: 3 | AA26: 32500 | AC26: 533810 | AD26: 533810_dungntt | AE26: 0 | BE26: 168600 | BF26: 498745 | BG26: 89200 | BH26: 756545 | BJ26: Rà soát để bàn giao trên CMS | BK26: 533810 | BL26: Thuỷ An | BM26: Phường An Cựu | BQ26: X | BR26: R | BS26: Bưu điện TT Thuận Hóa - Phú Xuân
A27: 25 | B27: 5310 | C27: Bưu điện TT Thuận Hóa - Phú Xuân | D27: Cá Nhân | E27: C019136875 | F27: Cá Nhân | G27: May store | H27: số nhà 18 kiệt 154 bà triệu, Phường Thuận Hóa, TP Huế | I27: 0365156019 | K27: C019136875 | M27: 285/2025/HĐ_BC-PHBC/BĐTP-MAYSTORE | N27: 46023 | T27: Đang hoạt động | U27: NGUYỄN BÁ TRÀ MI | V27: CTN009; CTN007 | W27: GTG021; GTG047;GTG021 | Y27: 774.02914 | Z27: 398 | AA27: 8262457 | AC27: 533810 | AD27: 533810_dungntt | AE27: Không cho xem hàng, gọi cho người gửi trước khi chuyển hoàn | BE27: 0 | BF27: 8262457 | BG27: 4628564 | BH27: 12891021 | BJ27: Rà soát để bàn giao trên CMS | BK27: 533810 | BL27: Thuỷ An | BM27: Phường An Cựu | BN27: X | BQ27: X | BS27: Bưu điện TT Thuận Hóa - Phú Xuân
A28: 26 | B28: 5310 | C28: Bưu điện TT Thuận Hóa - Phú Xuân | D28: Cá Nhân | E28: C001395300 | F28: Cá Nhân | G28: Cô Lộc | H28: 4/4/4 Kiệt 33 An Dương Vương An Cựu TP Huế | I28: 0918581215 | K28: C001395300 | M28: 49/HĐBC/BĐTPH-CL | N28: 44256 | T28: Đang hoạt động | U28: PHẠM THỊ THANH UYÊN | V28: CTN001; CTN007 | W28: GTG021; GTG071 | Y28: 861.35211 | Z28: 41 | AA28: 1974993 | AC28: 533810 | AD28: 533810_dungntt | AE28: gọi sđt trên đơn hàng | BE28: 0 | BF28: 1974993 | BG28: 848485 | BH28: 2823478 | BJ28: Phát - Long | BK28: 533810 | BL28: Thuỷ An | BM28: Phường An Cựu | BQ28: X | BS28: Bưu điện TT Thuận Hóa - Phú Xuân
A29: 27 | B29: 5310 | C29: Bưu điện TT Thuận Hóa - Phú Xuân | D29: Cá Nhân | E29: C019370201 | F29: Cá Nhân | G29: Võ Nhật Bình | H29: Thôn Bằng Lãng, Thuỷ Bằng, Phường Thủy Xuân, TP Huế | I29: 0867676257 | K29: C019370201 | M29: 01/2026-HĐ/BCCP/BDTPHUE-BDAC-DNB | N29: 46050 | T29: Đang hoạt động | U29: NGUYỄN BÁ TRÀ MI | V29: CTN009 | W29: GTG021 | Y29: 1300 | Z29: 5 | AA29: 166668 | AC29: 533810 | AD29: 533810_dungntt | AE29: Hàng dễ vỡ, vui lòng nhẹ tay; Cho xem hàng không cho đụng vào hàng | BE29: 0 | BF29: 166668 | BG29: 277780 | BH29: 444448 | BJ29: Rà soát để bàn giao trên CMS | BK29: 533810 | BL29: Thuỷ An | BM29: Phường An Cựu | BN29: X | BQ29: X | BS29: Bưu điện TT Thuận Hóa - Phú Xuân
A30: 28 | B30: 5310 | C30: Bưu điện TT Thuận Hóa - Phú Xuân | D30: Key Account | E30: T017963860 | F30: Key Account | G30: Trung Tâm HCC Phường An Cựu | H30: 67A Hoàng Quốc Việt, Phường An Cựu, TP Huế | J30: Phan Đăng Phú Khánh | K30: T017963860 | M30: 175/2025/HĐ_BC-PHBC/BĐTT-TTPVHCCPAC | N30: 45839 | O30: Không xác định | P30: Không có | Q30: 01 tháng/lần Trong 03 - 05 ngày làm việc tiếp theo kể từ ngày nhận được hoá đơn GTGT hợp lệ | T30: Đang hoạt động | U30: ĐẶNG TUẤN VŨ | V30: Dịch vụ HCC, luân chuyển hồ sơ HCC, KT1, EMS, Chuyển phát bưu phẩm trong nước và quốc tế | X30: Tài liệu | Y30: 0.05125 | Z30: 0.4 | AA30: 11000 | AB30: My VNP | AC30: 533810 | AD30: 533810_dungntt | AF30: Thực hiện theo quy định của TCT | AK30: 356400 | AL30: Đang làm thanh toán | BC30: X | BE30: 1091340 | BF30: 1058397 | BG30: 399441 | BH30: 2549178 | BI30: Hồ sơ vật lý và hồ sơ điện tử | BJ30: Lan - Thắm | BK30: 533810 | BL30: Thuỷ An | BM30: Phường An Cựu | BN30: X | BQ30: X | BR30: X | BS30: Bưu điện TT Thuận Hóa - Phú Xuân
A31: 29 | B31: 5310 | C31: Bưu điện TT Thuận Hóa - Phú Xuân | D31: Tổ Chức | E31: T019531120 | F31: Tổ Chức | G31: CÔNG TY TNHH DỊCH VỤ SẢN XUẤT PDM VIỆT NAM | H31: 314 Văn Thánh, phường Kim Long, Thành Phố Huế, Việt Nam | K31: T019531120 | M31: 18 /2026/ HĐ¬BC-PHBC/BĐTPHUE-PDM | N31: 46079 | T31: Đang hoạt động | U31: NGUYỄN BÁ TRÀ MI | AC31: 533810 | BE31: 0 | BF31: 0 | BG31: 0 | BH31: 0 | BJ31: Rà soát để bàn giao trên CMS | BK31: 533810 | BL31: Thuỷ An | BM31: Phường An Cựu | BS31: Bưu điện TT Thuận Hóa - Phú Xuân
